<?xml version="1.0"?>
<sdf version="1.6">
    <model name="turtlebot3_waffle"> 
      <pose>0.0 0.0 0.0 0.0 0.0 0.0</pose>

      <link name="base_footprint"/>

      <link name="base_link">

        <inertial>
          <pose>0 0 0.015 0 0 0</pose>
          <inertia>
            <ixx>0.001</ixx>
            <ixy>0.000</ixy>
            <ixz>0.000</ixz>
            <iyy>0.001</iyy>
            <iyz>0.000</iyz>
            <izz>0.001</izz>
          </inertia>
          <mass>1.0</mass>
        </inertial>

        <collision name="base_collision">
          <pose>0 0 0.015 0 0 0</pose>
          <geometry>
            <box/>
          </geometry>
        </collision>

        <visual name="base_visual">
          <pose>0 0 0.015 0 0 0</pose>
          <geometry>
            <mesh>
              <uri>model://turtlebot3_common/meshes/waffle_base.dae</uri>
              <scale>0.001 0.001 0.001</scale>
            </mesh>
          </geometry>
        </visual>
      </link>

      <link name="l_front_wheel">

        <inertial>
          <pose>0.0575 -0.0675 0.035 1.570796 0 0</pose>
          <inertia>
            <ixx>0.001</ixx>
            <ixy>0.000</ixy>
            <ixz>0.000</ixz>
            <iyy>0.001</iyy>
            <iyz>0.000</iyz>
            <izz>0.001</izz>
          </inertia>
          <mass>0.1</mass>
        </inertial>

        <collision>
          <pose>0.0575 -0.0675 0.035 1.570796 0 0</pose>
          <geometry>
            <cylinder>
              <radius>0.035</radius>
              <length>0.025</length>
            </cylinder>
          </geometry>
          <surface>
            <!-- This friction pamareter don't contain reliable data!! -->
            <friction>
              <ode>
                <mu>100000.0</mu>
                <mu2>100000.0</mu2>
                <fdir1>0 0 0</fdir1>
                <slip1>0.0</slip1>
                <slip2>0.0</slip2>
              </ode>
            </friction>
            <contact>
              <ode>
                <soft_cfm>0</soft_cfm>
                <soft_erp>0.2</soft_erp>
                <kp>1e+5</kp>
                <kd>1</kd>
                <max_vel>0.01</max_vel>
                <min_depth>0.001</min_depth>
              </ode>
            </contact>
          </surface>
        </collision>

        <visual>
          <pose>0.0575 -0.0675 0.035 1.570796 0 0</pose>
          <geometry>
            <mesh>
              <uri>model://turtlebot3_common/meshes/tire.dae</uri>
              <scale>0.001 0.001 0.001</scale>
            </mesh>
          </geometry>
        </visual>
      </link>

      <link name="r_front_wheel">
        <inertial>
          <pose>0.0575 0.0675 0.035 1.570796 0 0</pose>
          <inertia>
            <ixx>0.001</ixx>
            <ixy>0.000</ixy>
            <ixz>0.000</ixz>
            <iyy>0.001</iyy>
            <iyz>0.000</iyz>
            <izz>0.001</izz>
          </inertia>
          <mass>0.1</mass>
        </inertial>
      
        <collision>
          <pose>0.0575 0.0675 0.035 1.570796 0 0</pose>
          <geometry>
            <cylinder>
              <radius>0.035</radius>
              <length>0.025</length>
            </cylinder>
          </geometry>
          <surface>
            <!-- This friction pamareter don't contain reliable data!! -->
            <friction>
              <ode>
                <mu>100000.0</mu>
                <mu2>100000.0</mu2>
                <fdir1>0 0 0</fdir1>
                <slip1>0.0</slip1>
                <slip2>0.0</slip2>
              </ode>
            </friction>
            <contact>
              <ode>
                <soft_cfm>0</soft_cfm>
                <soft_erp>0.2</soft_erp>
                <kp>1e+5</kp>
                <kd>1</kd>
                <max_vel>0.01</max_vel>
                <min_depth>0.001</min_depth>
              </ode>
            </contact>
          </surface>
        </collision>

        <visual>
          <pose>0.0575 0.0675 0.035 1.570796 0 0</pose>
          <geometry>
            <mesh>
              <uri>model://turtlebot3_common/meshes/tire.dae</uri>
              <scale>0.001 0.001 0.001</scale>
            </mesh>
          </geometry>
        </visual>

      </link>

        
        
      <link name="r_back_wheel_link">

        <inertial>
          <pose>-0.0575 0.0675 0.035 1.570796 0 0</pose>
          <inertia>
            <ixx>0.001</ixx>
            <ixy>0.000</ixy>
            <ixz>0.000</ixz>
            <iyy>0.001</iyy>
            <iyz>0.000</iyz>
            <izz>0.001</izz>
          </inertia>
          <mass>0.1</mass>
        </inertial>
      
        <collision>
          <pose>-0.0575 0.0675 0.035 1.570796 0 0</pose>
          <geometry>
            <cylinder>
              <radius>0.035</radius>
              <length>0.025</length>
            </cylinder>
          </geometry>
          <surface>
            <!-- This friction pamareter don't contain reliable data!! -->
            <friction>
              <ode>
                <mu>100000.0</mu>
                <mu2>100000.0</mu2>
                <fdir1>0 0 0</fdir1>
                <slip1>0.0</slip1>
                <slip2>0.0</slip2>
              </ode>
            </friction>
            <contact>
              <ode>
                <soft_cfm>0</soft_cfm>
                <soft_erp>0.2</soft_erp>
                <kp>1e+5</kp>
                <kd>1</kd>
                <max_vel>0.01</max_vel>
                <min_depth>0.001</min_depth>
              </ode>
            </contact>
          </surface>
        </collision>
        <visual>
          <pose>-0.0575 0.0675 0.035 1.570796 0 0</pose>
          <geometry>
            <mesh>
              <uri>model://turtlebot3_common/meshes/tire.dae</uri>
              <scale>0.001 0.001 0.001</scale>
            </mesh>
          </geometry>
        </visual>
      </link>
        
      <link name="l_back_wheel">

        <inertial>
          <pose>-0.0575 -0.0675 0.035 1.570796 0 0</pose>
          <inertia>
            <ixx>0.001</ixx>
            <ixy>0.000</ixy>
            <ixz>0.000</ixz>
            <iyy>0.001</iyy>
            <iyz>0.000</iyz>
            <izz>0.001</izz>
          </inertia>
          <mass>0.1</mass>
        </inertial>
      
        <collision>
          <pose>-0.0575 -0.0675 0.035 1.570796 0 0</pose>
          <geometry>
            <cylinder>
              <radius>0.032</radius>
              <length>0.025</length>
            </cylinder>
          </geometry>
          <surface>
            <!-- This friction pamareter don't contain reliable data!! -->
            <friction>
              <ode>
                <mu>100000.0</mu>
                <mu2>100000.0</mu2>
                <fdir1>0 0 0</fdir1>
                <slip1>0.0</slip1>
                <slip2>0.0</slip2>
              </ode>
            </friction>
            <contact>
              <ode>
                <soft_cfm>0</soft_cfm>
                <soft_erp>0.2</soft_erp>
                <kp>1e+5</kp>
                <kd>1</kd>
                <max_vel>0.01</max_vel>
                <min_depth>0.001</min_depth>
              </ode>
            </contact>
          </surface>
        </collision>

        <visual>
          <pose>-0.0575 -0.0675 0.035 1.570796 0 0</pose>
          <geometry>
            <mesh>
              <uri>model://turtlebot3_common/meshes/tire.dae</uri>
              <scale>0.001 0.001 0.001</scale>
            </mesh>
          </geometry>
        </visual>

      </link>

                   
          
      
      <joint name="base_joint" type="fixed">
        <parent>base_footprint</parent>
        <child>base_link</child>
        <pose>0.0 0.0 0.015 0 0 0</pose>
      </joint>

      <joint name="l_front_wheel_joint" type="revolute">
        <parent>base_link</parent>
        <child>l_front_wheel</child>
        <pose>0.0575 -0.0675 0.035 1.570796 0 0</pose>
        <axis>
          <xyz>0 0 1</xyz>
        </axis>
      </joint>

      <joint name="r_front_wheel_joint" type="revolute">
        <parent>base_link</parent>
        <child>r_front_wheel</child>
        <pose>0.0575 0.0675 0.035 1.570796 0 0</pose>
        <axis>
          <xyz>0 0 1</xyz>
        </axis>
      </joint>

      <joint name="r_back_wheel_joint" type="revolute">
        <parent>base_link</parent>
        <child>r_back_wheel</child>
        <pose>-0.0575 0.0675 0.035 1.570796 0 0</pose>
        <axis>
          <xyz>0 0 1</xyz>
        </axis>
      </joint>
        
        
        
      <joint name="l_back_wheel_joint" type="revolute">
        <parent>base_link</parent>
        <child>l_back_wheel_link</child>
        <pose>-0.0575 -0.0675 0.035 1.570796 0 0</pose>
        <axis>
          <xyz>0 0 1</xyz>
        </axis>
      </joint>
        


<!--
      <plugin name="turtlebot3_diff_drive" filename="libgazebo_ros_diff_drive.so">

        <ros>
          <!-- <namespace>/tb3</namespace> -->
          <!--since gazebo_plugins publish tf topic in global namespace /tf only and it
            cannot be remapped like (namespace/tf) through launch arguments -->
          <remapping>/tf:=tf</remapping>
        </ros>

        <update_rate>30</update_rate>

        <!-- wheels -->
        <left_joint>wheel_left_joint</left_joint>
        <right_joint>wheel_right_joint</right_joint>

        <!-- kinematics -->
        <wheel_separation>0.287</wheel_separation>
        <wheel_diameter>0.066</wheel_diameter>

        <!-- limits -->
        <max_wheel_torque>20</max_wheel_torque>
        <max_wheel_acceleration>1.0</max_wheel_acceleration>

        <command_topic>cmd_vel</command_topic>

        <!-- output -->
        <publish_odom>true</publish_odom>
        <publish_odom_tf>true</publish_odom_tf>
        <publish_wheel_tf>false</publish_wheel_tf>

        <odometry_topic>odom</odometry_topic>
        <odometry_frame>odom</odometry_frame>
        <robot_base_frame>base_footprint</robot_base_frame>

      </plugin>

      <plugin name="turtlebot3_joint_state" filename="libgazebo_ros_joint_state_publisher.so">
        <ros>
          <!-- <namespace>/tb3</namespace> -->
            <remapping>~/out:=joint_states</remapping>
        </ros>
        <update_rate>30</update_rate>
        <joint_name>wheel_left_joint</joint_name>
        <joint_name>wheel_right_joint</joint_name>
      </plugin>
-->
    </model>
</sdf>
