<?xml version="1.0" ?>
<robot name="turtlebot3_waffle" xmlns:xacro="http://ros.org/wiki/xacro">
    <link name="base_footprint"/>
    <link name="base_link">
        <visual>
            <origin xyz="0.0 0.0 0.135" rpy="0 0 0"/>
            <geometry>
                <box size="0.10 0.195 0.225"/>
            </geometry>
            <material name="gray">
                <color rgba="0.5 0.5 0.5 1.0"/>
            </material>
        </visual>
        <collision>
            <origin xyz="-0.08 0 0.03" rpy="0 0 0"/>
            <geometry>
                <box size="0.10 0.195 0.225"/>
            </geometry>
        </collision>
    </link>

    <joint name="base_footprint_fixed" type="fixed">
        <origin xyz="0 0 0" rpy="0 0 0" />
        <parent link="base_footprint"/>
        <child link="base_link"/>
    </joint>

    <link name="l_front_wheel">
        <visual>
            <origin xyz="-0.0925 0.0625 0.03" rpy="1.570796 0 0"/>
            <geometry>
                <cylinder radius="0.03" length="0.025"/>
            </geometry>
            <material name="dark_gray">
                <color rgba="0.0 0.0 0.8 1.0"/>
            </material>
        </visual>
        <collision>
            <origin xyz="0 0 0" rpy="1.570796 0 0"/>
            <geometry>
                <cylinder radius="0.03" length="0.025"/>
            </geometry>
        </collision>
    </link>

    <link name="r_front_wheel">
        <visual>
            <origin xyz="0.0925 0.0625 0.03" rpy="1.570796 0 0"/>
            <geometry>
                <cylinder radius="0.03" length="0.025"/>
            </geometry>
            <material name="dark_gray">
                <color rgba="0.2 0.2 0.2 1.0"/>
            </material>
        </visual>
        <collision>
            <origin xyz="0 0 0" rpy="1.570796 0 0"/>
            <geometry>
                <cylinder radius="0.03" length="0.025"/>
            </geometry>
        </collision>
    </link>

    <joint name="l_front_wheel_joint" type="continuous">
        <origin xyz="-0.0925 0.0625 0.03" rpy="1.570796 0 0" />
        <parent link="base_link"/>
        <child link="l_front_wheel"/>
        <axis xyz="0 1 0"/>
    </joint>

    <joint name="r_front_wheel_joint" type="continuous">
        <origin xyz="0.0925 0.0625 0.03" rpy="1.570796 0 0" />
        <parent link="base_link"/>
        <child link="r_front_wheel"/>
        <axis xyz="0 1 0"/>
    </joint>

    <link name="l_back_wheel">
        <visual>
            <origin xyz="-0.0925 -0.0625 0.03" rpy="1.570796 0 0"/>
            <geometry>
                <cylinder radius="0.03" length="0.025"/>
            </geometry>
            <material name="dark_gray">
                <color rgba="0.2 0.2 0.2 1.0"/>
            </material>
        </visual>
        <collision>
            <origin xyz="0 0 0" rpy="1.570796 0 0"/>
            <geometry>
                <cylinder radius="0.03" length="0.025"/>
            </geometry>
        </collision>
    </link>

    <link name="r_back_wheel">
        <visual>
            <origin xyz="0.0925 -0.0625 0.03" rpy="1.570796 0 0"/>
            <geometry>
                <cylinder radius="0.03" length="0.025"/>
            </geometry>
            <material name="dark_gray">
                <color rgba="0.2 0.2 0.2 1.0"/>
            </material>
        </visual>
        <collision>
            <origin xyz="0 0 0" rpy="1.570796 0 0"/>
            <geometry>
                <cylinder radius="0.03" length="0.025"/>
            </geometry>
        </collision>
    </link>

    <joint name="l_back_wheel_joint" type="continuous">
        <origin xyz="-0.0925 -0.0625 0.03" rpy="1.570796 0 0" />
        <parent link="base_link"/>
        <child link="l_back_wheel"/>
        <axis xyz="0 1 0"/>
    </joint>

    <joint name="r_back_wheel_joint" type="continuous">
        <origin xyz="0.0925 -0.0625 0.03" rpy="1.570796 0 0" />
        <parent link="base_link"/>
        <child link="r_back_wheel"/>
        <axis xyz="0 1 0"/>
    </joint>
    
    <joint name="base_link_fixed" type="fixed">
        <origin xyz="0 0 0" rpy="0 0 0" />
        <parent link="base_link"/>
        <child link="laser"/>
    </joint>
    
    <link name="laser">
        <visual>
            <origin xyz="0 0 0.03" rpy="0 0 0"/>
            <geometry>
                <cylinder radius="0.035" length="0.06"/>
            </geometry>
            <material name="dark_gray">
                <color rgba="0.2 0.2 0.2 1.0"/>
            </material>
        </visual>
        <collision>
            <origin xyz="0 0 0.03" rpy="0 0 0"/>
            <geometry>
                <cylinder radius="0.035" length="0.06"/>
            </geometry>
        </collision>
    </link>

    <joint name="laser" type="continuous">
        <origin xyz="0 0 0" rpy="0 0 0" />
        <parent link="base_link"/>
        <child link="laser"/>
        <axis xyz="0 1 0"/>
    </joint>
</robot>

