<?xml version="1.0" ?>
<robot name="turtlebot3_waffle" xmlns:xacro="http://ros.org/wiki/xacro">
  <!-- <xacro:include filename="$(find turtlebot3_description)/urdf/common_properties.urdf"/>

  <xacro:property name="r200_cam_rgb_px" value="0.005"/>
  <xacro:property name="r200_cam_rgb_py" value="0.018"/>
  <xacro:property name="r200_cam_rgb_pz" value="0.013"/>
  <xacro:property name="r200_cam_depth_offset" value="0.01"/> -->

  <!-- Init colour -->
  <material name="black">
      <color rgba="0.0 0.0 0.0 1.0"/>
  </material>

  <material name="dark">
    <color rgba="0.3 0.3 0.3 1.0"/>
  </material>

  <material name="light_black">
    <color rgba="0.4 0.4 0.4 1.0"/>
  </material>

  <material name="blue">
    <color rgba="0.0 0.0 0.8 1.0"/>
  </material>

  <material name="green">
    <color rgba="0.0 0.8 0.0 1.0"/>
  </material>

  <material name="grey">
    <color rgba="0.5 0.5 0.5 1.0"/>
  </material>

  <material name="orange">
    <color rgba="1.0 0.4235 0.0392 1.0"/>
  </material>

  <material name="brown">
    <color rgba="0.8706 0.8118 0.7647 1.0"/>
  </material>

  <material name="red">
    <color rgba="0.8 0.0 0.0 1.0"/>
  </material>

  <material name="white">
    <color rgba="1.0 1.0 1.0 1.0"/>
  </material>

  <link name="base_footprint"/>

  <joint name="base_joint" type="fixed">
    <parent link="base_footprint"/>
    <child link="base_link"/>
    <origin xyz="0 0 0.010" rpy="0 0 0"/>
  </joint>

  <link name="base_link">
    <visual>
      <origin xyz="-0.064 0 0.0" rpy="0 0 0"/>
      <geometry>
        <mesh filename="package://turtlebot3_description/meshes/bases/waffle_base.stl" scale="0.001 0.001 0.001"/>
      </geometry>
      <material name="light_black"/>
    </visual>

    <collision>
      <origin xyz="-0.064 0 0.047" rpy="0 0 0"/>
      <geometry>
        <box size="0.266 0.266 0.094"/>
      </geometry>
    </collision>

    <inertial>
      <origin xyz="0 0 0" rpy="0 0 0"/>
      <mass value="1.3729096e+00"/>
      <inertia ixx="8.7002718e-03" ixy="-4.7576583e-05" ixz="1.1160499e-04"
               iyy="1.6421012e-02" iyz="2.1841149e-06"
               izz="1.8260632e-02"/>
    </inertial>
  </link>

  <joint name="front_left_wheel_joint" type="continuous">
    <parent link="base_link"/>
    <child link="front_left_wheel"/>
    <origin xyz="0.077 0.066 0.0" rpy="0 0 0"/>
    <axis xyz="0 0 1"/>
  </joint>

  <link name="front_left_wheel">
    <visual>
      <origin xyz="0.077 0.066 0.0" rpy="0 0 0"/>
      <geometry>
        <cylinder length="0.032" radius="0.032"/>
      </geometry>
      <material name="red"/>
    </visual>

    <collision>
      <origin xyz="0.077 0.066 0.0" rpy="0 0 0"/>
      <geometry>
        <cylinder length="0.032" radius="0.032"/>
      </geometry>
    </collision>

    <inertial>
      <origin xyz="0 0 0" rpy="0 0 0"/>
      <mass value="0.141"/>
      <inertia ixx="2.62e-04" ixy="0" ixz="0"
               iyy="2.62e-04" iyz="0"
               izz="2.62e-04"/>
             
  <link name="front_left_wheel_driver">
    <visual>
      <origin xyz="0.077 0.066 0.0" rpy="0 0 0"/>
      <geometry>
        <cylinder length="0.032" radius="0.032"/>
      </geometry>
      <material name="red"/>
    </visual>

    <collision>
      <origin xyz="0.077 0.066 0.0" rpy="0 0 0"/>
      <geometry>
        <cylinder length="0.032" radius="0.032"/>
      </geometry>
    </collision>

    <inertial>
      <origin xyz="0 0 0" rpy="0 0 0"/>
      <mass value="0.141"/>
      <inertia ixx="2.62e-04" ixy="0" ixz="0"
               iyy="2.62e-04" iyz="0"
               izz="2.62e-04"/>
    </inertial>
  </link>

  <joint name="front_right_wheel_joint" type="continuous">
    <parent link="base_link"/>
    <child link="front_right_wheel"/>
    <origin xyz="0.077 -0.066 0.0" rpy="0 0 0"/>
    <axis xyz="0 0 1"/>
  </joint>

  <link name="front_right_wheel">
    <visual>
      <origin xyz="0.077 -0.066 0.0" rpy="0 0 0"/>
      <geometry>
        <cylinder length="0.032" radius="0.032"/>
      </geometry>
      <material name="green"/>
    </visual>

    <collision>
      <origin xyz="0.077 -0.066 0.0" rpy="0 0 0"/>
      <geometry>
        <cylinder length="0.032" radius="0.032"/>
      </geometry>
    </collision>

    <inertial>
      <origin xyz="0 0 0" rpy="0 0 0"/>
      <mass value="0.141"/>
      <inertia ixx="2.62e-04" ixy="0" ixz="0"
               iyy="2.62e-04" iyz="0"
               izz="2.62e-04"/>
    </inertial>
  </link>

  <joint name="rear_left_wheel_joint" type="continuous">
    <parent link="base_link"/>
    <child link="rear_left_wheel"/>
    <origin xyz="-0.077 0.066 0.0" rpy="0 0 0"/>
    <axis xyz="0 0 1"/>
  </joint>

  <link name="rear_left_wheel">
    <visual>
      <origin xyz="-0.077 0.066 0.0" rpy="0 0 0"/>
      <geometry>
        <cylinder length="0.032" radius="0.032"/>
      </geometry>
      <material name="blue"/>
    </visual>

    <collision>
      <origin xyz="-0.077 0.066 0.0" rpy="0 0 0"/>
      <geometry>
        <cylinder length="0.032" radius="0.032"/>
      </geometry>
    </collision>

    <inertial>
      <origin xyz="0 0 0" rpy="0 0 0"/>
      <mass value="0.141"/>
      <inertia ixx="2.62e-04" ixy="0" ixz="0"
               iyy="2.62e-04" iyz="0"
               izz="2.62e-04"/>
    </inertial>
  </link>

  <joint name="rear_right_wheel_joint" type="continuous">
    <parent link="base_link"/>
    <child link="rear_right_wheel"/>
    <origin xyz="-0.077 -0.066 0.0" rpy="0 0 0"/>
    <axis xyz="0 0 1"/>
  </joint>

  <link name="rear_right_wheel">
    <visual>
      <origin xyz="-0.077 -0.066 0.0" rpy="0 0 0"/>
      <geometry>
        <cylinder length="0.032" radius="0.032"/>
      </geometry>
      <material name="orange"/>
    </visual>

    <collision>
      <origin xyz="-0.077 -0.066 0.0" rpy="0 0 0"/>
      <geometry>
        <cylinder length="0.032" radius="0.032"/>
      </geometry>
    </collision>

    <inertial>
      <origin xyz="0 0 0" rpy="0 0 0"/>
      <mass value="0.141"/>
      <inertia ixx="2.62e-04" ixy="0" ixz="0"
               iyy="2.62e-04" iyz="0"
               izz="2.62e-04"/>
    </inertial>
  </link>

  <!-- Define joints -->
  <joint name="front_left_wheel_motor_joint" type="continuous">
    <parent link="front_left_wheel"/>
    <child link="front_left_wheel_motor"/>
    <origin xyz="0 0 0" rpy="0 0 0"/>
    <axis xyz="0 0 1"/>
  </joint>

  <joint name="front_right_wheel_motor_joint" type="continuous">
    <parent link="front_right_wheel"/>
    <child link="front_right_wheel_motor"/>
    <origin xyz="0 0 0" rpy="0 0 0"/>
    <axis xyz="0 0 1"/>
  </joint>

  <joint name="rear_left_wheel_motor_joint" type="continuous">
    <parent link="rear_left_wheel"/>
    <child link="rear_left_wheel_motor"/>
    <origin xyz="0 0 0" rpy="0 0 0"/>
    <axis xyz="0 0 1"/>
  </joint>

  <joint name="rear_right_wheel_motor_joint" type="continuous">
    <parent link="rear_right_wheel"/>
    <child link="rear_right_wheel_motor"/>
    <origin xyz="0 0 0" rpy="0 0 0"/>
    <axis xyz="0 0 1"/>
  </joint>

  <joint name="front_left_wheel_driver_joint" type="fixed">
    <parent link="front_left_wheel_motor"/>
    <child link="front_left_wheel_driver"/>
    <origin xyz="0 0 0" rpy="0 0 0"/>
  </joint>

  <link name="front_left_wheel_motor">
    <visual>
      <origin xyz="0 0 0" rpy="0 0 0"/>
      <geometry>
        <cylinder length="0.01" radius="0.02"/>
      </geometry>
      <material name="white"/>
    </visual>

    <collision>
      <origin xyz="0 0 0" rpy="0 0 0"/>
      <geometry>
        <cylinder length="0.01" radius="0.02"/>
      </geometry>
    </collision>

    <inertial>
      <origin xyz="0 0 0" rpy="0 0 0"/>
      <mass value="0.01"/>
      <inertia ixx="8.33e-06" ixy="0" ixz="0"
               iyy="8.33e-06" iyz="0"
               izz="8.33e-06"/>
    </inertial>
  </link>

  <joint name="front_right_wheel_driver_joint" type="fixed">
    <parent link="front_right_wheel_motor"/>
    <child link="front_right_wheel_driver"/>
    <origin xyz="0 0 0" rpy="0 0 0"/>
  </joint>

  <link name="front_right_wheel_motor">
    <visual>
      <origin xyz="0 0 0" rpy="0 0 0"/>
      <geometry>
        <cylinder length="0.01" radius="0.02"/>
      </geometry>
      <material name="white"/>
    </visual>

    <collision>
      <origin xyz="0 0 0" rpy="0 0 0"/>
      <geometry>
        <cylinder length="0.01" radius="0.02"/>
      </geometry>
    </collision>

    <inertial>
      <origin xyz="0 0 0" rpy="0 0 0"/>
      <mass value="0.01"/>
      <inertia ixx="8.33e-06" ixy="0" ixz="0"
               iyy="8.33e-06" iyz="0"
               izz="8.33e-06"/>
    </inertial>
  </link>

  <joint name="rear_left_wheel_driver_joint" type="fixed">
    <parent link="rear_left_wheel_motor"/>
    <child link="rear_left_wheel_driver"/>
    <origin xyz="0 0 0" rpy="0 0 0"/>
  </joint>

  <link name="rear_left_wheel_motor">
    <visual>
      <origin xyz="0 0 0" rpy="0 0 0"/>
      <geometry>
        <cylinder length="0.01" radius="0.02"/>
      </geometry>
      <material name="white"/>
    </visual>

    <collision>
      <origin xyz="0 0 0" rpy="0 0 0"/>
      <geometry>
        <cylinder length="0.01" radius="0.02"/>
      </geometry>
    </collision>

    <inertial>
      <origin xyz="0 0 0" rpy="0 0 0"/>
      <mass value="0.01"/>
      <inertia ixx="8.33e-06" ixy="0" ixz="0"
               iyy="8.33e-06" iyz="0"
               izz="8.33e-06"/>
    </inertial>
  </link>

  <joint name="rear_right_wheel_driver_joint" type="fixed">
    <parent link="rear_right_wheel_motor"/>
    <child link="rear_right_wheel_driver"/>
    <origin xyz="0 0 0" rpy="0 0 0"/>
  </joint>

  <link name="rear_right_wheel_motor">
    <visual>
      <origin xyz="0 0 0" rpy="0 0 0"/>
      <geometry>
        <cylinder length="0.01" radius="0.02"/>
      </geometry>
      <material name="white"/>
    </visual>

    <collision>
      <origin xyz="0 0 0" rpy="0 0 0"/>
      <geometry>
        <cylinder length="0.01" radius="0.02"/>
      </geometry>
    </collision>

    <inertial>
      <origin xyz="0 0 0" rpy="0 0 0"/>
      <mass value="0.01"/>
      <inertia ixx="8.33e-06" ixy="0" ixz="0"
               iyy="8.33e-06" iyz="0"
               izz="8.33e-06"/>
    </inertial>
  </link>

  <!-- Define transmission -->
  <transmission name="front_left_wheel_motor_transmission">
    <type>transmission_interface/SimpleTransmission</type>
    <joint name="front_left_wheel_driver_joint">
      <hardwareInterface>hardware_interface/EffortJointInterface</hardwareInterface>
    </joint>
    <actuator name="front_left_wheel_motor_joint">
      <hardwareInterface>hardware_interface/EffortJointInterface</hardwareInterface>
      <mechanicalReduction>1</mechanicalReduction>
    </actuator>
  </transmission>

  <transmission name="front_right_wheel_motor_transmission">
    <type>transmission_interface/SimpleTransmission</type>
    <joint name="front_right_wheel_driver_joint">
      <hardwareInterface>hardware_interface/EffortJointInterface</hardwareInterface>
    </joint>
    <actuator name="front_right_wheel_motor_joint">
      <hardwareInterface>hardware_interface/EffortJointInterface</hardwareInterface>
      <mechanicalReduction>1</mechanicalReduction>
    </actuator>
  </transmission>

  <transmission name="rear_left_wheel_motor_transmission">
    <type>transmission_interface/SimpleTransmission</type>
    <joint name="rear_left_wheel_driver_joint">
      <hardwareInterface>hardware_interface/EffortJointInterface</hardwareInterface>
    </joint>
    <actuator name="rear_left_wheel_motor_joint">
      <hardwareInterface>hardware_interface/EffortJointInterface</hardwareInterface>
      <mechanicalReduction>1</mechanicalReduction>
    </actuator>
  </transmission>

  <transmission name="rear_right_wheel_motor_transmission">
    <type>transmission_interface/SimpleTransmission</type>
    <joint name="rear_right_wheel_driver_joint">
      <hardwareInterface>hardware_interface/EffortJointInterface</hardwareInterface>
    </joint>
    <actuator name="rear_right_wheel_motor_joint">
      <hardwareInterface>hardware_interface/EffortJointInterface</hardwareInterface>
      <mechanicalReduction>1</mechanicalReduction>
    </actuator>
  </transmission>

</robot>
